<?xml version="1.0"?>
<robot xmlns:xacro="http://www.ros.org/wiki/xacro" name="unitree_go2">

  <!-- Robot parameters -->
  <xacro:property name="body_length" value="0.366" />
  <xacro:property name="body_width" value="0.094" />
  <xacro:property name="body_height" value="0.114" />
  <xacro:property name="leg_length" value="0.213" />
  <xacro:property name="thigh_length" value="0.213" />
  <xacro:property name="calf_length" value="0.213" />

  <!-- Materials -->
  <material name="black">
    <color rgba="0.0 0.0 0.0 1.0"/>
  </material>

  <material name="white">
    <color rgba="1.0 1.0 1.0 1.0"/>
  </material>

  <material name="grey">
    <color rgba="0.5 0.5 0.5 1.0"/>
  </material>

  <material name="red">
    <color rgba="0.8 0.0 0.0 1.0"/>
  </material>

  <!-- Base link -->
  <link name="base_link">
    <visual>
      <origin xyz="0 0 0" rpy="0 0 0"/>
      <geometry>
        <box size="${body_length} ${body_width} ${body_height}"/>
      </geometry>
      <material name="black"/>
    </visual>
    <collision>
      <origin xyz="0 0 0" rpy="0 0 0"/>
      <geometry>
        <box size="${body_length} ${body_width} ${body_height}"/>
      </geometry>
    </collision>
    <inertial>
      <origin xyz="0 0 0" rpy="0 0 0"/>
      <mass value="15.0"/>
      <inertia ixx="0.07" ixy="0.0" ixz="0.0"
               iyy="0.26" iyz="0.0"
               izz="0.26"/>
    </inertial>
  </link>

  <!-- Front left leg -->
  <link name="FL_hip">
    <visual>
      <origin xyz="0 0 0" rpy="0 0 0"/>
      <geometry>
        <cylinder radius="0.02" length="0.04"/>
      </geometry>
      <material name="grey"/>
    </visual>
    <collision>
      <origin xyz="0 0 0" rpy="0 0 0"/>
      <geometry>
        <cylinder radius="0.02" length="0.04"/>
      </geometry>
    </collision>
    <inertial>
      <origin xyz="0 0 0" rpy="0 0 0"/>
      <mass value="0.696"/>
      <inertia ixx="0.001" ixy="0.0" ixz="0.0"
               iyy="0.001" iyz="0.0"
               izz="0.001"/>
    </inertial>
  </link>

  <link name="FL_thigh">
    <visual>
      <origin xyz="0 0 -0.1065" rpy="0 0 0"/>
      <geometry>
        <cylinder radius="0.01" length="${thigh_length}"/>
      </geometry>
      <material name="grey"/>
    </visual>
    <collision>
      <origin xyz="0 0 -0.1065" rpy="0 0 0"/>
      <geometry>
        <cylinder radius="0.01" length="${thigh_length}"/>
      </geometry>
    </collision>
    <inertial>
      <origin xyz="0 0 -0.1065" rpy="0 0 0"/>
      <mass value="1.013"/>
      <inertia ixx="0.005" ixy="0.0" ixz="0.0"
               iyy="0.005" iyz="0.0"
               izz="0.001"/>
    </inertial>
  </link>

  <link name="FL_calf">
    <visual>
      <origin xyz="0 0 -0.1065" rpy="0 0 0"/>
      <geometry>
        <cylinder radius="0.008" length="${calf_length}"/>
      </geometry>
      <material name="grey"/>
    </visual>
    <collision>
      <origin xyz="0 0 -0.1065" rpy="0 0 0"/>
      <geometry>
        <cylinder radius="0.008" length="${calf_length}"/>
      </geometry>
    </collision>
    <inertial>
      <origin xyz="0 0 -0.1065" rpy="0 0 0"/>
      <mass value="0.226"/>
      <inertia ixx="0.002" ixy="0.0" ixz="0.0"
               iyy="0.002" iyz="0.0"
               izz="0.0001"/>
    </inertial>
  </link>

  <link name="FL_foot">
    <visual>
      <origin xyz="0 0 0" rpy="0 0 0"/>
      <geometry>
        <sphere radius="0.01"/>
      </geometry>
      <material name="red"/>
    </visual>
    <collision>
      <origin xyz="0 0 0" rpy="0 0 0"/>
      <geometry>
        <sphere radius="0.01"/>
      </geometry>
    </collision>
    <inertial>
      <origin xyz="0 0 0" rpy="0 0 0"/>
      <mass value="0.05"/>
      <inertia ixx="0.00001" ixy="0.0" ixz="0.0"
               iyy="0.00001" iyz="0.0"
               izz="0.00001"/>
    </inertial>
  </link>

  <!-- Front right leg -->
  <link name="FR_hip">
    <visual>
      <origin xyz="0 0 0" rpy="0 0 0"/>
      <geometry>
        <cylinder radius="0.02" length="0.04"/>
      </geometry>
      <material name="grey"/>
    </visual>
    <collision>
      <origin xyz="0 0 0" rpy="0 0 0"/>
      <geometry>
        <cylinder radius="0.02" length="0.04"/>
      </geometry>
    </collision>
    <inertial>
      <origin xyz="0 0 0" rpy="0 0 0"/>
      <mass value="0.696"/>
      <inertia ixx="0.001" ixy="0.0" ixz="0.0"
               iyy="0.001" iyz="0.0"
               izz="0.001"/>
    </inertial>
  </link>

  <link name="FR_thigh">
    <visual>
      <origin xyz="0 0 -0.1065" rpy="0 0 0"/>
      <geometry>
        <cylinder radius="0.01" length="${thigh_length}"/>
      </geometry>
      <material name="grey"/>
    </visual>
    <collision>
      <origin xyz="0 0 -0.1065" rpy="0 0 0"/>
      <geometry>
        <cylinder radius="0.01" length="${thigh_length}"/>
      </geometry>
    </collision>
    <inertial>
      <origin xyz="0 0 -0.1065" rpy="0 0 0"/>
      <mass value="1.013"/>
      <inertia ixx="0.005" ixy="0.0" ixz="0.0"
               iyy="0.005" iyz="0.0"
               izz="0.001"/>
    </inertial>
  </link>

  <link name="FR_calf">
    <visual>
      <origin xyz="0 0 -0.1065" rpy="0 0 0"/>
      <geometry>
        <cylinder radius="0.008" length="${calf_length}"/>
      </geometry>
      <material name="grey"/>
    </visual>
    <collision>
      <origin xyz="0 0 -0.1065" rpy="0 0 0"/>
      <geometry>
        <cylinder radius="0.008" length="${calf_length}"/>
      </geometry>
    </collision>
    <inertial>
      <origin xyz="0 0 -0.1065" rpy="0 0 0"/>
      <mass value="0.226"/>
      <inertia ixx="0.002" ixy="0.0" ixz="0.0"
               iyy="0.002" iyz="0.0"
               izz="0.0001"/>
    </inertial>
  </link>

  <link name="FR_foot">
    <visual>
      <origin xyz="0 0 0" rpy="0 0 0"/>
      <geometry>
        <sphere radius="0.01"/>
      </geometry>
      <material name="red"/>
    </visual>
    <collision>
      <origin xyz="0 0 0" rpy="0 0 0"/>
      <geometry>
        <sphere radius="0.01"/>
      </geometry>
    </collision>
    <inertial>
      <origin xyz="0 0 0" rpy="0 0 0"/>
      <mass value="0.05"/>
      <inertia ixx="0.00001" ixy="0.0" ixz="0.0"
               iyy="0.00001" iyz="0.0"
               izz="0.00001"/>
    </inertial>
  </link>

  <!-- Rear left leg -->
  <link name="RL_hip">
    <visual>
      <origin xyz="0 0 0" rpy="0 0 0"/>
      <geometry>
        <cylinder radius="0.02" length="0.04"/>
      </geometry>
      <material name="grey"/>
    </visual>
    <collision>
      <origin xyz="0 0 0" rpy="0 0 0"/>
      <geometry>
        <cylinder radius="0.02" length="0.04"/>
      </geometry>
    </collision>
    <inertial>
      <origin xyz="0 0 0" rpy="0 0 0"/>
      <mass value="0.696"/>
      <inertia ixx="0.001" ixy="0.0" ixz="0.0"
               iyy="0.001" iyz="0.0"
               izz="0.001"/>
    </inertial>
  </link>

  <link name="RL_thigh">
    <visual>
      <origin xyz="0 0 -0.1065" rpy="0 0 0"/>
      <geometry>
        <cylinder radius="0.01" length="${thigh_length}"/>
      </geometry>
      <material name="grey"/>
    </visual>
    <collision>
      <origin xyz="0 0 -0.1065" rpy="0 0 0"/>
      <geometry>
        <cylinder radius="0.01" length="${thigh_length}"/>
      </geometry>
    </collision>
    <inertial>
      <origin xyz="0 0 -0.1065" rpy="0 0 0"/>
      <mass value="1.013"/>
      <inertia ixx="0.005" ixy="0.0" ixz="0.0"
               iyy="0.005" iyz="0.0"
               izz="0.001"/>
    </inertial>
  </link>

  <link name="RL_calf">
    <visual>
      <origin xyz="0 0 -0.1065" rpy="0 0 0"/>
      <geometry>
        <cylinder radius="0.008" length="${calf_length}"/>
      </geometry>
      <material name="grey"/>
    </visual>
    <collision>
      <origin xyz="0 0 -0.1065" rpy="0 0 0"/>
      <geometry>
        <cylinder radius="0.008" length="${calf_length}"/>
      </geometry>
    </collision>
    <inertial>
      <origin xyz="0 0 -0.1065" rpy="0 0 0"/>
      <mass value="0.226"/>
      <inertia ixx="0.002" ixy="0.0" ixz="0.0"
               iyy="0.002" iyz="0.0"
               izz="0.0001"/>
    </inertial>
  </link>

  <link name="RL_foot">
    <visual>
      <origin xyz="0 0 0" rpy="0 0 0"/>
      <geometry>
        <sphere radius="0.01"/>
      </geometry>
      <material name="red"/>
    </visual>
    <collision>
      <origin xyz="0 0 0" rpy="0 0 0"/>
      <geometry>
        <sphere radius="0.01"/>
      </geometry>
    </collision>
    <inertial>
      <origin xyz="0 0 0" rpy="0 0 0"/>
      <mass value="0.05"/>
      <inertia ixx="0.00001" ixy="0.0" ixz="0.0"
               iyy="0.00001" iyz="0.0"
               izz="0.00001"/>
    </inertial>
  </link>

  <!-- Rear right leg -->
  <link name="RR_hip">
    <visual>
      <origin xyz="0 0 0" rpy="0 0 0"/>
      <geometry>
        <cylinder radius="0.02" length="0.04"/>
      </geometry>
      <material name="grey"/>
    </visual>
    <collision>
      <origin xyz="0 0 0" rpy="0 0 0"/>
      <geometry>
        <cylinder radius="0.02" length="0.04"/>
      </geometry>
    </collision>
    <inertial>
      <origin xyz="0 0 0" rpy="0 0 0"/>
      <mass value="0.696"/>
      <inertia ixx="0.001" ixy="0.0" ixz="0.0"
               iyy="0.001" iyz="0.0"
               izz="0.001"/>
    </inertial>
  </link>

  <link name="RR_thigh">
    <visual>
      <origin xyz="0 0 -0.1065" rpy="0 0 0"/>
      <geometry>
        <cylinder radius="0.01" length="${thigh_length}"/>
      </geometry>
      <material name="grey"/>
    </visual>
    <collision>
      <origin xyz="0 0 -0.1065" rpy="0 0 0"/>
      <geometry>
        <cylinder radius="0.01" length="${thigh_length}"/>
      </geometry>
    </collision>
    <inertial>
      <origin xyz="0 0 -0.1065" rpy="0 0 0"/>
      <mass value="1.013"/>
      <inertia ixx="0.005" ixy="0.0" ixz="0.0"
               iyy="0.005" iyz="0.0"
               izz="0.001"/>
    </inertial>
  </link>

  <link name="RR_calf">
    <visual>
      <origin xyz="0 0 -0.1065" rpy="0 0 0"/>
      <geometry>
        <cylinder radius="0.008" length="${calf_length}"/>
      </geometry>
      <material name="grey"/>
    </visual>
    <collision>
      <origin xyz="0 0 -0.1065" rpy="0 0 0"/>
      <geometry>
        <cylinder radius="0.008" length="${calf_length}"/>
      </geometry>
    </collision>
    <inertial>
      <origin xyz="0 0 -0.1065" rpy="0 0 0"/>
      <mass value="0.226"/>
      <inertia ixx="0.002" ixy="0.0" ixz="0.0"
               iyy="0.002" iyz="0.0"
               izz="0.0001"/>
    </inertial>
  </link>

  <link name="RR_foot">
    <visual>
      <origin xyz="0 0 0" rpy="0 0 0"/>
      <geometry>
        <sphere radius="0.01"/>
      </geometry>
      <material name="red"/>
    </visual>
    <collision>
      <origin xyz="0 0 0" rpy="0 0 0"/>
      <geometry>
        <sphere radius="0.01"/>
      </geometry>
    </collision>
    <inertial>
      <origin xyz="0 0 0" rpy="0 0 0"/>
      <mass value="0.05"/>
      <inertia ixx="0.00001" ixy="0.0" ixz="0.0"
               iyy="0.00001" iyz="0.0"
               izz="0.00001"/>
    </inertial>
  </link>

  <!-- Joints -->
  <!-- Front Left Leg Joints -->
  <joint name="FL_hip_joint" type="revolute">
    <parent link="base_link"/>
    <child link="FL_hip"/>
    <origin xyz="0.183 0.047 0" rpy="0 0 0"/>
    <axis xyz="1 0 0"/>
    <limit lower="-1.047" upper="1.047" effort="23.7" velocity="30.1"/>
  </joint>

  <joint name="FL_thigh_joint" type="revolute">
    <parent link="FL_hip"/>
    <child link="FL_thigh"/>
    <origin xyz="0 0 0" rpy="0 0 0"/>
    <axis xyz="0 1 0"/>
    <limit lower="-0.663" upper="2.966" effort="23.7" velocity="30.1"/>
  </joint>

  <joint name="FL_calf_joint" type="revolute">
    <parent link="FL_thigh"/>
    <child link="FL_calf"/>
    <origin xyz="0 0 -0.213" rpy="0 0 0"/>
    <axis xyz="0 1 0"/>
    <limit lower="-2.721" upper="-0.837" effort="35.55" velocity="20.06"/>
  </joint>

  <joint name="FL_foot_joint" type="fixed">
    <parent link="FL_calf"/>
    <child link="FL_foot"/>
    <origin xyz="0 0 -0.213" rpy="0 0 0"/>
  </joint>

  <!-- Front Right Leg Joints -->
  <joint name="FR_hip_joint" type="revolute">
    <parent link="base_link"/>
    <child link="FR_hip"/>
    <origin xyz="0.183 -0.047 0" rpy="0 0 0"/>
    <axis xyz="1 0 0"/>
    <limit lower="-1.047" upper="1.047" effort="23.7" velocity="30.1"/>
  </joint>

  <joint name="FR_thigh_joint" type="revolute">
    <parent link="FR_hip"/>
    <child link="FR_thigh"/>
    <origin xyz="0 0 0" rpy="0 0 0"/>
    <axis xyz="0 1 0"/>
    <limit lower="-0.663" upper="2.966" effort="23.7" velocity="30.1"/>
  </joint>

  <joint name="FR_calf_joint" type="revolute">
    <parent link="FR_thigh"/>
    <child link="FR_calf"/>
    <origin xyz="0 0 -0.213" rpy="0 0 0"/>
    <axis xyz="0 1 0"/>
    <limit lower="-2.721" upper="-0.837" effort="35.55" velocity="20.06"/>
  </joint>

  <joint name="FR_foot_joint" type="fixed">
    <parent link="FR_calf"/>
    <child link="FR_foot"/>
    <origin xyz="0 0 -0.213" rpy="0 0 0"/>
  </joint>

  <!-- Rear Left Leg Joints -->
  <joint name="RL_hip_joint" type="revolute">
    <parent link="base_link"/>
    <child link="RL_hip"/>
    <origin xyz="-0.183 0.047 0" rpy="0 0 0"/>
    <axis xyz="1 0 0"/>
    <limit lower="-1.047" upper="1.047" effort="23.7" velocity="30.1"/>
  </joint>

  <joint name="RL_thigh_joint" type="revolute">
    <parent link="RL_hip"/>
    <child link="RL_thigh"/>
    <origin xyz="0 0 0" rpy="0 0 0"/>
    <axis xyz="0 1 0"/>
    <limit lower="-2.966" upper="0.663" effort="23.7" velocity="30.1"/>
  </joint>

  <joint name="RL_calf_joint" type="revolute">
    <parent link="RL_thigh"/>
    <child link="RL_calf"/>
    <origin xyz="0 0 -0.213" rpy="0 0 0"/>
    <axis xyz="0 1 0"/>
    <limit lower="-2.721" upper="-0.837" effort="35.55" velocity="20.06"/>
  </joint>

  <joint name="RL_foot_joint" type="fixed">
    <parent link="RL_calf"/>
    <child link="RL_foot"/>
    <origin xyz="0 0 -0.213" rpy="0 0 0"/>
  </joint>

  <!-- Rear Right Leg Joints -->
  <joint name="RR_hip_joint" type="revolute">
    <parent link="base_link"/>
    <child link="RR_hip"/>
    <origin xyz="-0.183 -0.047 0" rpy="0 0 0"/>
    <axis xyz="1 0 0"/>
    <limit lower="-1.047" upper="1.047" effort="23.7" velocity="30.1"/>
  </joint>

  <joint name="RR_thigh_joint" type="revolute">
    <parent link="RR_hip"/>
    <child link="RR_thigh"/>
    <origin xyz="0 0 0" rpy="0 0 0"/>
    <axis xyz="0 1 0"/>
    <limit lower="-2.966" upper="0.663" effort="23.7" velocity="30.1"/>
  </joint>

  <joint name="RR_calf_joint" type="revolute">
    <parent link="RR_thigh"/>
    <child link="RR_calf"/>
    <origin xyz="0 0 -0.213" rpy="0 0 0"/>
    <axis xyz="0 1 0"/>
    <limit lower="-2.721" upper="-0.837" effort="35.55" velocity="20.06"/>
  </joint>

  <joint name="RR_foot_joint" type="fixed">
    <parent link="RR_calf"/>
    <child link="RR_foot"/>
    <origin xyz="0 0 -0.213" rpy="0 0 0"/>
  </joint>

  <!-- RPLiDAR mount -->
  <link name="lidar_mount">
    <visual>
      <origin xyz="0 0 0" rpy="0 0 0"/>
      <geometry>
        <cylinder radius="0.03" length="0.02"/>
      </geometry>
      <material name="black"/>
    </visual>
    <collision>
      <origin xyz="0 0 0" rpy="0 0 0"/>
      <geometry>
        <cylinder radius="0.03" length="0.02"/>
      </geometry>
    </collision>
    <inertial>
      <origin xyz="0 0 0" rpy="0 0 0"/>
      <mass value="0.1"/>
      <inertia ixx="0.0001" ixy="0.0" ixz="0.0"
               iyy="0.0001" iyz="0.0"
               izz="0.0001"/>
    </inertial>
  </link>

  <joint name="lidar_mount_joint" type="fixed">
    <parent link="base_link"/>
    <child link="lidar_mount"/>
    <origin xyz="0 0 0.077" rpy="0 0 0"/>
  </joint>

  <!-- RPLiDAR sensor frame (matches your launch file configuration) -->
  <link name="laser"/>

  <joint name="laser_joint" type="fixed">
    <parent link="lidar_mount"/>
    <child link="laser"/>
    <origin xyz="0 0 0.01" rpy="0 0 3.14159"/>
  </joint>

</robot>
